<?xml version="1.0" encoding="utf-8"?>
<!-- This URDF was automatically created by SolidWorks to URDF Exporter! Originally created by Stephen Brawner (brawner@gmail.com) 
     Commit Version: 1.6.0-4-g7f85cfe  Build Version: 1.6.7995.38578
     For more information, please see http://wiki.ros.org/sw_urdf_exporter -->
<robot
  name="new_car">
  <link
    name="base_link">
    <inertial>
      <origin
        xyz="-0.0053092 -6.6041E-17 0.018692"
        rpy="0 0 0" />
      <mass
        value="1000.782" />
      <inertia
        ixx="0.080482"
        ixy="2.0627E-16"
        ixz="-0.0029975"
        iyy="0.062244"
        iyz="-3.5525E-17"
        izz="0.13176" />
    </inertial>
    <visual>
      <origin
        xyz="0 0 0"
        rpy="0 0 0" />
      <geometry>
        <mesh
          filename="package://new_car/meshes/base_link.STL" />
      </geometry>
      <material
        name="">
        <color
          rgba="0.89804 0.91765 0.92941 1" />
      </material>
    </visual>
    <collision>
      <origin
        xyz="0 0 0"
        rpy="0 0 0" />
      <geometry>
        <mesh
          filename="package://new_car/meshes/base_link.STL" />
      </geometry>
    </collision>
  </link>
  <link
    name="castwheel">
    <inertial>
      <origin
        xyz="-0.063618 0.0087179 -0.089187"
        rpy="0 0 0" />
      <mass
        value="8.9511" />
      <inertia
        ixx="0.030635"
        ixy="8.6736E-19"
        ixz="0"
        iyy="0.030635"
        iyz="4.3368E-19"
        izz="0.030635" />
    </inertial>
    <visual>
      <origin
        xyz="0 0 0"
        rpy="0 0 0" />
      <geometry>
        <mesh
          filename="package://new_car/meshes/castwheel.STL" />
      </geometry>
      <material
        name="">
        <color
          rgba="0.89804 0.91765 0.92941 1" />
      </material>
    </visual>
    <collision>
      <origin
        xyz="0 0 0"
        rpy="0 0 0" />
      <geometry>
        <mesh
          filename="package://new_car/meshes/castwheel.STL" />
      </geometry>
    </collision>
  </link>
  <joint
    name="castwheel_joint"
    type="continuous">
    <origin
      xyz="1.422E-05 0.00125 -0.0925"
      rpy="1.7999 -0.42435 -2.2705" />
    <parent
      link="base_link" />
    <child
      link="castwheel" />
    <axis
      xyz="0.57888 -0.079328 0.81154" />
  </joint>
  <link
    name="leftwheel">
    <inertial>
      <origin
        xyz="6.245E-17 3.8164E-17 0.024994"
        rpy="0 0 0" />
      <mass
        value="9.4472" />
      <inertia
        ixx="0.05564"
        ixy="2.1684E-18"
        ixz="3.8272E-17"
        iyy="0.05564"
        iyz="4.9148E-17"
        izz="0.10734" />
    </inertial>
    <visual>
      <origin
        xyz="0 0 0"
        rpy="0 0 0" />
      <geometry>
        <mesh
          filename="package://new_car/meshes/leftwheel.STL" />
      </geometry>
      <material
        name="">
        <color
          rgba="0.89804 0.91765 0.92941 1" />
      </material>
    </visual>
    <collision>
      <origin
        xyz="0 0 0"
        rpy="0 0 0" />
      <geometry>
        <mesh
          filename="package://new_car/meshes/leftwheel.STL" />
      </geometry>
    </collision>
  </link>
  <joint
    name="leftwheel_joint"
    type="continuous">
    <origin
      xyz="-0.055 0.20001 -0.035"
      rpy="-1.5708 -0.10501 0" />
    <parent
      link="base_link" />
    <child
      link="leftwheel" />
    <axis
      xyz="0 0 1" />
  </joint>
  <link
    name="rightwheel">
    <inertial>
      <origin
        xyz="-4.5103E-17 8.3267E-17 -0.024994"
        rpy="0 0 0" />
      <mass
        value="9.4472" />
      <inertia
        ixx="0.05564"
        ixy="-5.2042E-18"
        ixz="2.2335E-17"
        iyy="0.05564"
        iyz="-2.5045E-17"
        izz="0.10734" />
    </inertial>
    <visual>
      <origin
        xyz="0 0 0"
        rpy="0 0 0" />
      <geometry>
        <mesh
          filename="package://new_car/meshes/rightwheel.STL" />
      </geometry>
      <material
        name="">
        <color
          rgba="0.89804 0.91765 0.92941 1" />
      </material>
    </visual>
    <collision>
      <origin
        xyz="0 0 0"
        rpy="0 0 0" />
      <geometry>
        <mesh
          filename="package://new_car/meshes/rightwheel.STL" />
      </geometry>
    </collision>
  </link>
  <joint
    name="rightwheel_joint"
    type="continuous">
    <origin
      xyz="-0.0549999999999977 -0.200006469136745 -0.035"
      rpy="-1.5707963267949 0.939281776145976 0" />
    <parent
      link="base_link" />
    <child
      link="rightwheel" />
    <axis
      xyz="0 0 1" />
  </joint>
  <link
    name="link1">
    <inertial>
      <origin
        xyz="-0.020977 -1.0815E-17 0.15"
        rpy="0 0 0" />
      <mass
        value="7.0138" />
      <inertia
        ixx="0.07535"
        ixy="-5.8005E-18"
        ixz="-6.1527E-18"
        iyy="0.065314"
        iyz="5.722E-18"
        izz="0.035458" />
    </inertial>
    <visual>
      <origin
        xyz="0 0 0"
        rpy="0 0 0" />
      <geometry>
        <mesh
          filename="package://new_car/meshes/link1.STL" />
      </geometry>
      <material
        name="">
        <color
          rgba="1 1 1 0.35" />
      </material>
    </visual>
    <collision>
      <origin
        xyz="0 0 0"
        rpy="0 0 0" />
      <geometry>
        <mesh
          filename="package://new_car/meshes/link1.STL" />
      </geometry>
    </collision>
  </link>
  <joint
    name="joint1"
    type="revolute">
    <origin
      xyz="0 0 0.05"
      rpy="0 0 0" />
    <parent
      link="base_link" />
    <child
      link="link1" />
    <axis
      xyz="0 0 1" />
    <limit
      lower="-3.14"
      upper="3.14"
      effort="50"
      velocity="1.5" />
  </joint>
  <link
    name="link2">
    <inertial>
      <origin
        xyz="0.13517 -2.2714E-16 0"
        rpy="0 0 0" />
      <mass
        value="1.2926" />
      <inertia
        ixx="0.0033047"
        ixy="-8.1315E-19"
        ixz="2.0289E-19"
        iyy="0.012724"
        iyz="-4.5666E-19"
        izz="0.012724" />
    </inertial>
    <visual>
      <origin
        xyz="0 0 0"
        rpy="0 0 0" />
      <geometry>
        <mesh
          filename="package://new_car/meshes/link2.STL" />
      </geometry>
      <material
        name="">
        <color
          rgba="1 1 1 0.35" />
      </material>
    </visual>
    <collision>
      <origin
        xyz="0 0 0"
        rpy="0 0 0" />
      <geometry>
        <mesh
          filename="package://new_car/meshes/link2.STL" />
      </geometry>
    </collision>
  </link>
  <joint
    name="joint2"
    type="prismatic">
    <origin
      xyz="0 0 0.25"
      rpy="0 0 0" />
    <parent
      link="link1" />
    <child
      link="link2" />
    <axis
      xyz="0 0 1" />
    <limit
      lower="-0.2"
      upper="0"
      effort="10"
      velocity="1.5" />
  </joint>
  <link
    name="link3">
    <inertial>
      <origin
        xyz="-0.0942552370102731 -6.76542155630955E-17 2.22044604925031E-16"
        rpy="0 0 0" />
      <mass
        value="2.28787766720044" />
      <inertia
        ixx="0.00274830854445484"
        ixy="-4.08608693755474E-18"
        ixz="1.73045038288303E-18"
        iyy="0.0226475881994451"
        iyz="-5.69070397270195E-18"
        izz="0.022339682500004" />
    </inertial>
    <visual>
      <origin
        xyz="0 0 0"
        rpy="0 0 0" />
      <geometry>
        <mesh
          filename="package://new_car/meshes/link3.STL" />
      </geometry>
      <material
        name="">
        <color
          rgba="1 1 1 0.35" />
      </material>
    </visual>
    <collision>
      <origin
        xyz="0 0 0"
        rpy="0 0 0" />
      <geometry>
        <mesh
          filename="package://new_car/meshes/link3.STL" />
      </geometry>
    </collision>
  </link>
  <joint
    name="joint3"
    type="prismatic">
    <origin
      xyz="0.3 0 0"
      rpy="0 0 0" />
    <parent
      link="link2" />
    <child
      link="link3" />
    <axis
      xyz="-1 0 0" />
    <limit
      lower="0"
      upper="0.26"
      effort="10"
      velocity="1.5" />
  </joint>
  <link
    name="link4">
    <inertial>
      <origin
        xyz="0.076653 -1.0929E-16 -5.5511E-17"
        rpy="0 0 0" />
      <mass
        value="2.5617" />
      <inertia
        ixx="0.0037141"
        ixy="5.421E-20"
        ixz="-3.2609E-19"
        iyy="0.023523"
        iyz="3.0633E-19"
        izz="0.022599" />
    </inertial>
    <visual>
      <origin
        xyz="0 0 0"
        rpy="0 0 0" />
      <geometry>
        <mesh
          filename="package://new_car/meshes/link4.STL" />
      </geometry>
      <material
        name="">
        <color
          rgba="1 1 1 0.35" />
      </material>
    </visual>
    <collision>
      <origin
        xyz="0 0 0"
        rpy="0 0 0" />
      <geometry>
        <mesh
          filename="package://new_car/meshes/link4.STL" />
      </geometry>
    </collision>
  </link>
  <joint
    name="joint4"
    type="revolute">
    <origin
      xyz="0.1216 0 0"
      rpy="0 0 0" />
    <parent
      link="link3" />
    <child
      link="link4" />
    <axis
      xyz="0 1 0" />
    <limit
      lower="-1.57"
      upper="1.57"
      effort="50"
      velocity="1.5" />
  </joint>
  <link
    name="link5">
    <inertial>
      <origin
        xyz="0.023312 -2.6888E-17 5.5511E-17"
        rpy="0 0 0" />
      <mass
        value="1.7726" />
      <inertia
        ixx="0.0086712"
        ixy="-4.3029E-19"
        ixz="-4.9659E-19"
        iyy="0.0047611"
        iyz="-1.3921E-06"
        izz="0.0050018" />
    </inertial>
    <visual>
      <origin
        xyz="0 0 0"
        rpy="0 0 0" />
      <geometry>
        <mesh
          filename="package://new_car/meshes/link5.STL" />
      </geometry>
      <material
        name="">
        <color
          rgba="1 1 1 0.35" />
      </material>
    </visual>
    <collision>
      <origin
        xyz="0 0 0"
        rpy="0 0 0" />
      <geometry>
        <mesh
          filename="package://new_car/meshes/link5.STL" />
      </geometry>
    </collision>
  </link>
  <joint
    name="joint5"
    type="revolute">
    <origin
      xyz="0.25745 0 0"
      rpy="0 0 0" />
    <parent
      link="link4" />
    <child
      link="link5" />
    <axis
      xyz="1 0 0" />
    <limit
      lower="-3.14"
      upper="3.14"
      effort="50"
      velocity="1.5" />
  </joint>
  <link
    name="finger1">
    <inertial>
      <origin
        xyz="0.0431914558074192 0.00222291741094893 1.66533453693773E-16"
        rpy="0 0 0" />
      <mass
        value="0.0976142957842524" />
      <inertia
        ixx="3.3639206496037E-05"
        ixy="-1.20897051606813E-05"
        ixz="7.59655791198793E-20"
        iyy="0.000119799305634777"
        iyz="3.45196492914701E-20"
        izz="0.000112765888887376" />
    </inertial>
    <visual>
      <origin
        xyz="0 0 0"
        rpy="0 0 0" />
      <geometry>
        <mesh
          filename="package://new_car/meshes/finger1.STL" />
      </geometry>
      <material
        name="">
        <color
          rgba="1 1 1 0.35" />
      </material>
    </visual>
    <collision>
      <origin
        xyz="0 0 0"
        rpy="0 0 0" />
      <geometry>
        <mesh
          filename="package://new_car/meshes/finger1.STL" />
      </geometry>
    </collision>
  </link>
  <joint
    name="fin1"
    type="prismatic">
    <origin
      xyz="0.05 -0.076716 -0.00044365"
      rpy="0.0057829 0 0" />
    <parent
      link="link5" />
    <child
      link="finger1" />
    <axis
      xyz="0 -0.99998 0.0057829" />
    <limit
      lower="0"
      upper="0.05"
      effort="30"
      velocity="1" />
  </joint>
  <link
    name="finger2">
    <inertial>
      <origin
        xyz="0.043191 -0.0022229 2.1094E-15"
        rpy="0 0 0" />
      <mass
        value="0.097614" />
      <inertia
        ixx="3.3639E-05"
        ixy="1.209E-05"
        ixz="1.775E-20"
        iyy="0.0001198"
        iyz="1.1095E-19"
        izz="0.00011277" />
    </inertial>
    <visual>
      <origin
        xyz="0 0 0"
        rpy="0 0 0" />
      <geometry>
        <mesh
          filename="package://new_car/meshes/finger2.STL" />
      </geometry>
      <material
        name="">
        <color
          rgba="1 1 1 0.35" />
      </material>
    </visual>
    <collision>
      <origin
        xyz="0 0 0"
        rpy="0 0 0" />
      <geometry>
        <mesh
          filename="package://new_car/meshes/finger2.STL" />
      </geometry>
    </collision>
  </link>
  <joint
    name="fin2"
    type="prismatic">
    <origin
      xyz="0.05 0.077005 0.00044532"
      rpy="0.0057829 0 0" />
    <parent
      link="link5" />
    <child
      link="finger2" />
    <axis
      xyz="0 -0.99998 0.0057829" />
    <limit
      lower="0"
      upper="0"
      effort="30"
      velocity="1" />
    <mimic
      joint="fin1"
      multiplier="-1"
      offset="0" />
  </joint>
</robot>